Workbook
Name \C: #REF!
Name \h: #N/A
Name \X: #REF!
Name _\C: #REF!
Name _\h: #N/A
Name _\X: #REF!
Name __\C: #REF!
Name __\h: #N/A
Name __\X: #REF!
Name ___\C: #REF!
Name ___\h: #N/A
Name ___\X: #REF!
Name ____\h: #N/A
Name _____\h: #N/A
Name a: #REF!
Name aa: #REF!
Name aaa: #REF!
Name aaaaa: #REF!
Name aaaaaaa: #REF!
Name ab: #REF!
Name ALLOCATION: #REF!
Name b: #REF!
Name Badan: #REF!
Name bodenk: #REF!
Name Calculated_Relationship_HS12___HS07: #REF!
Name conf_status_code: #REF!
Name Corps: #REF!
Name d: #REF!
Name data_perusahaan: #REF!
Name datab: #REF!
Name dfghjk: #REF!
Name e: #REF!
Name f: #REF!
Name fd_rilis_1: #REF!,#REF!,#REF!,#REF!,#REF!
Name fd_rilis_2: #REF!,#REF!,#REF!,#REF!,#REF!
Name fd_sut_1: #REF!,#REF!,#REF!,#REF!,#REF!
Name fd_sut_2: #REF!,#REF!,#REF!,#REF!,#REF!
Name fd_sut_2010: #REF!,#REF!,#REF!,#REF!,#REF!
Name fg: #REF!
Name g: #REF!
Name gg: #REF!
Name H: #N/A
Name HH: #REF!:#REF!
Name hhh: #REF!
Name hidayat: #REF!
Name HS: #REF!
Name IDP_IDK: #REF!
Name input11: #REF!
Name input12: #REF!
Name input12a: #REF!
Name jk: #REF!
Name k: #REF!
Name kat_2010: #REF!,#REF!,#REF!,#REF!,#REF!,#REF!,#REF!,#REF!,#REF!
Name kat_rilis_1: #REF!,#REF!,#REF!,#REF!,#REF!,#REF!,#REF!,#REF!,#REF!
Name kat_rilis_2: #REF!,#REF!,#REF!,#REF!,#REF!,#REF!,#REF!,#REF!,#REF!
Name kat_sut_1: #REF!,#REF!,#REF!,#REF!,#REF!,#REF!,#REF!,#REF!,#REF!
Name kat_sut_2: #REF!,#REF!,#REF!,#REF!,#REF!,#REF!,#REF!,#REF!,#REF!
Name Kategori: #REF!:#REF!
Name kode_perusahaan: #REF!
Name Lapangan_Usaha: #REF!

Sheet BCD 185
B1: Tabel Input-Output Indonesia Transaksi Domestik Atas Dasar Harga Dasar (185 Produk), 2020
B2: (Juta Rupiah)
B4: Kode | C4: Produk | D4: 1 | E4: 2 | F4: 3 | G4: 4 | H4: 5 | I4: 6 | J4: 7 | K4: 8 | L4: 9 | M4: 10 | N4: 11 | O4: 12 | P4: 13 | Q4: 14 | R4: 15 | S4: 16 | T4: 17 | U4: 18 | V4: 19 | W4: 20 | X4: 21 | Y4: 22 | Z4: 23 | AA4: 24 | AB4: 25 | AC4: 26 | AD4: 27 | AE4: 28 | AF4: 29 | AG4: 30 | AH4: 31 | AI4: 32 | AJ4: 33 | AK4: 34 | AL4: 35 | AM4: 36 | AN4: 37 | AO4: 38 | AP4: 39 | AQ4: 40 | AR4: 41 | AS4: 42 | AT4: 43 | AU4: 44 | AV4: 45 | AW4: 46 | AX4: 47 | AY4: 48 | AZ4: 49 | BA4: 50 | BB4: 51 | BC4: 52 | BD4: 53 | BE4: 54 | BF4: 55 | BG4: 56 | BH4: 57 | BI4: 58 | BJ4: 59 | BK4: 60 | BL4: 61 | BM4: 62 | BN4: 63 | BO4: 64 | BP4: 65 | BQ4: 66 | BR4: 67 | BS4: 68 | BT4: 69 | BU4: 70 | BV4: 71 | BW4: 72 | BX4: 73 | BY4: 74 | BZ4: 75 | CA4: 76 | CB4: 77 | CC4: 78 | CD4: 79 | CE4: 80 | CF4: 81 | CG4: 82 | CH4: 83 | CI4: 84 | CJ4: 85 | CK4: 86 | CL4: 87 | CM4: 88 | CN4: 89 | CO4: 90 | CP4: 91 | CQ4: 92 | CR4: 93 | CS4: 94 | CT4: 95 | CU4: 96 | CV4: 97 | CW4: 98 | CX4: 99 | CY4: 100 | CZ4: 101 | DA4: 102 | DB4: 103 | DC4: 104 | DD4: 105 | DE4: 106 | DF4: 107 | DG4: 108 | DH4: 109 | DI4: 110 | DJ4: 111 | DK4: 112 | DL4: 113 | DM4: 114 | DN4: 115 | DO4: 116 | DP4: 117 | DQ4: 118 | DR4: 119 | DS4: 120 | DT4: 121 | DU4: 122 | DV4: 123 | DW4: 124 | DX4: 125 | DY4: 126 | DZ4: 127 | EA4: 128 | EB4: 129 | EC4: 130 | ED4: 131 | EE4: 132 | EF4: 133 | EG4: 134 | EH4: 135 | EI4: 136 | EJ4: 137 | EK4: 138 | EL4: 139 | EM4: 140 | EN4: 141 | EO4: 142 | EP4: 143 | EQ4: 144 | ER4: 145 | ES4: 146 | ET4: 147 | EU4: 148 | EV4: 149 | EW4: 150 | EX4: 151 | EY4: 152 | EZ4: 153 | FA4: 154 | FB4: 155 | FC4: 156 | FD4: 157 | FE4: 158 | FF4: 159 | FG4: 160 | FH4: 161 | FI4: 162 | FJ4: 163 | FK4: 164 | FL4: 165 | FM4: 166 | FN4: 167 | FO4: 168 | FP4: 169 | FQ4: 170 | FR4: 171 | FS4: 172 | FT4: 173 | FU4: 174 | FV4: 175 | FW4: 176 | FX4: 177 | FY4: 178 | FZ4: 179 | GA4: 180 | GB4: 181 | GC4: 182 | GD4: 183 | GE4: 184 | GF4: 185 | GG4: 1800 | GH4: 3011 | GI4: 3012 | GJ4: 3020 | GK4: 3030 | GL4: 3040 | GM4: 3050 | GN4: 3060 | GO4: 3090 | GP4: 3100 | GQ4: 4011 | GR4: 4012 | GS4: 4013 | GT4: 4019 | GU4: 5011 | GV4: 5012 | GW4: 5013 | GX4: 5019 | GY4: 6090 | GZ4: 7000 | HA4: 8000
D5: Padi | E5: Jagung | F5: Ubi jalar | G5: Ubi kayu | H5: Umbi-umbian lainnya | I5: Kacang tanah | J5: Kedelai | K5: Kacang-kacangan Lainnya | L5: Padi-padian dan Bahan Makanan Lainnya | M5: Sayur-sayuran | N5: Tanaman Hias dan Holtikultura Lainnya | O5: Tebu | P5: Tembakau | Q5: Tanaman serat | R5: Hasil Perkebunan Lainnya | S5: Buah-buahan | T5: Tanaman Biofarmaka | U5: Karet | V5: Kelapa | W5: Kelapa Sawit | X5: Kopi | Y5: Teh | Z5: Kakao | AA5: Cengkeh | AB5: Jambu Mete | AC5: Ternak dan Hasil-hasilnya kecuali Susu Segar | AD5: Susu segar | AE5: Unggas dan Hasil-hasilnya | AF5: Hasil Pemeliharaan Hewan Lainnya | AG5: Jasa Pertanian, Kehutanan dan Perikanan | AH5: Kayu | AI5: Hasil Hutan Lainnya | AJ5: Ikan | AK5: Udang dan crustacea lainnya | AL5: Biota air lainnya | AM5: Rumput laut dan sejenisnya | AN5: Batubara dan lignit | AO5: Minyak Bumi | AP5: Gas Bumi dan Panas Bumi | AQ5: Pasir besi dan bijih besi | AR5: Bijih Timah | AS5: Bijih Bauksit | AT5: Bijih Tembaga | AU5: Bijih Nikel | AV5: Barang Tambang Logam Lainnya | AW5: Bijih Emas | AX5: Bijih Perak | AY5: Barang Galian Segala Jenis | AZ5: Barang Tambang Mineral Bukan Logam | BA5: Garam Kasar | BB5: Jasa pertambangan minyak bumi dan gas alam | BC5: Jasa pertambangan dan penggalian lainnya | BD5: Hasil Pemotongan Hewan | BE5: Hasil Pengolahan dan Pengawetan Daging | BF5: Ikan Kering dan Ikan Asin | BG5: Hasil Pengolahan dan Pengawetan Ikan | BH5: Hasil Pengolahan dan Pengawetan Buah-buahan dan Sayur-sayuran | BI5: Minyak Hewani dan Minyak Nabati | BJ5: Minyak kelapa dan Kopra | BK5: Makanan dan Minuman Terbuat dari Susu | BL5: Tepung Lainnya | BM5: Tepung Terigu, Pati dan Produk Pati | BN5: Hasil Penggilingan Padi dan Penyosohan Beras | BO5: Roti, Biskuit dan Sejenisnya | BP5: Gula | BQ5: Coklat dan Kembang Gula | BR5: Mie, Macaroni dan Sejenisnya | BS5: Kopi Olahan | BT5: Teh Olahan | BU5: Kedele Olahan | BV5: Makanan Lainnya | BW5: Makanan Hewan Olahan | BX5: Minuman Beralkohol | BY5: Minuman Tak Beralkohol | BZ5: Rokok | CA5: Tembakau Olahan | CB5: Benang | CC5: Tekstil | CD5: Permadani,Tali dan Penutup Lantai Lainnya | CE5: Produk Tekstil Lainnya | CF5: Barang-barang Rajutan dan Sulaman/Bordiran | CG5: Pakaian Jadi | CH5: Hasil Pengawetan dan Penyamakan Kulit | CI5: Barang-barang dari Kulit | CJ5: Alas Kaki | CK5: Kayu Gergajian dan Olahan | CL5: Kayu Lapis dan Sejenisnya | CM5: Bahan Bangunan dari Kayu | CN5: Barang-barang Lainnya dari Kayu, Gabus, Bambu dan Rotan | CO5: Bubur Kertas | CP5: Kertas | CQ5: Barang-Barang dari Kertas dan Karton | CR5: Barang Cetakan | CS5: Barang-barang Lainnya dari Bahan Bukan Logam dan Produk dari Batubara | CT5: Barang-barang Hasil Kilang Minyak dan Gas serta Produk Batubara | CU5: Kimia Dasar Kecuali Pupuk | CV5: Pupuk | CW5: Plastik, Karet dan Serat Buatan | CX5: Pestisida | CY5: Cat dan tinta cetak | CZ5: Vernis dan Lak | DA5: Sabun dan bahan pembersih | DB5: Kosmetik | DC5: Barang-barang kimia lainnya | DD5: Produk farmasi | DE5: Obat Tradisional | DF5: Ban | DG5: Karet Remah dan Karet Asap | DH5: Barang-barang Lainnya dari Karet | DI5: Barang-Barang dari Plastik | DJ5: Kaca dan Barang-barang dari Kaca | DK5: Barang-Barang dari tanah liat, keramik dan porselen | DL5: Semen | DM5: Besi dan Baja Dasar | DN5: Logam Dasar Bukan Besi | DO5: Barang-barang hasil Pengecoran logam | DP5: Bahan Bangunan dari Logam | DQ5: Senjata dan amunisi, metalurgi dan jasa pembuatan barang logam | DR5: Alat-alat dapur, pertukangan, perabot rumahtangga dan kantor dari logam | DS5: Barang-barang Logam Lainnya | DT5: Barang-barang Elektronik, Komunikasi dan Perlengkapannya | DU5: Alat Ukur, Fotografi, Optik dan Jam | DV5: Mesin Pembangkit dan Motor Listrik | DW5: Mesin Listrik dan Perlengkapannya | DX5: Baterai dan Aki | DY5: Perlengkapan Listrik Lainnya | DZ5: Alat Listrik Untuk Rumah Tangga | EA5: Mesin Penggerak Mula | EB5: Mesin untuk keperluan kantor dan akunting, dan bagian serta perlengkapannya | EC5: Mesin lainnya dan perlengkapannya | ED5: Kendaraan Bermotor Kecuali Sepeda Motor | EE5: Kapal dan Jasa Perbaikannya | EF5: Kereta Api dan Jasa Perbaikannya | EG5: Pesawat Terbang dan Jasa Perbaikannya | EH5: Alat Pengangkutan Lainnya | EI5: Sepeda Motor | EJ5: Perabotan Rumah Tangga dan Kantor Selain dari Logam | EK5: Perhiasan | EL5: Alat-Alat Musik | EM5: Alat-Alat Olahraga | EN5: Alat Permainan dan mainan anak-anak | EO5: Alat Kedokteran | EP5: Barang-barang hasil industri pengolahan lainnya | EQ5: Jasa perawatan dan perbaikan produk-produk logam pabrikan, mesin-mesin dan peralatan | ER5: Listrik | ES5: Hasil gas alam dan buatan, pengadaan uap air/air panas, udara dingin dan produk es | ET5: Pengadaan Air | EU5: Pengelolaan Sampah, Limbah dan Daur Ulang | EV5: Bangunan Tempat Tinggal dan Bukan Tempat Tinggal | EW5: Bangunan dan Instalasi Listrik, Gas, Air Minum dan Komunikasi | EX5: Prasarana Pertanian | EY5: Jalan, Jembatan, dan Pelabuhan | EZ5: Bangunan Lainnya | FA5: Perdagangan Mobil dan Sepeda Motor | FB5: Reparasi dan Perawatan Mobil dan Sepeda Motor | FC5: Perdagangan selain Mobil dan Sepeda Motor | FD5: Jasa Angkutan Rel | FE5: Jasa Angkutan Darat Selain Angkutan Rel | FF5: Jasa Angkutan Laut | FG5: Jasa Angkutan Sungai danau dan Penyeberangan | FH5: Jasa Angkutan Udara | FI5: Jasa Penunjang Angkutan | FJ5: Jasa Pos dan Kurir | FK5: Penyediaan Akomodasi | FL5: Penyediaan Makan dan Minum | FM5: Hasil-hasil Penerbitan | FN5: Jasa Penyiaran dan pemrograman, Film dan Hasil Perekaman Suara | FO5: Jasa Telekomunikasi | FP5: Jasa Konsultasi komputer dan teknologi informasi | FQ5: Jasa Keuangan Perbankan | FR5: Jasa asuransi | FS5: Jasa dana Pensiun | FT5: Jasa Lembaga Keuangan Lainnya | FU5: Jasa Real Estate | FV5: Jasa Profesional, Ilmiah dan Teknis | FW5: Jasa Persewaan dan Jasa Penunjang Usaha | FX5: Jasa Pemerintahan Umum | FY5: Jasa Pendidikan Pemerintah | FZ5: Jasa Kesehatan Pemerintah | GA5: Jasa Pemerintahan Lainnya | GB5: Jasa Pendidikan Swasta | GC5: Jasa Kesehatan dan Kegiatan Sosial Swasta | GD5: Jasa Kesenian, Hiburan dan Rekreasi | GE5: Reparasi Barang Rumahtangga dan Pribadi Lainnya | GF5: Jasa Lainnya | GG5: Total Permintaan Antara | GH5: Konsumsi Rumah Tangga | GI5: Konsumsi LNPRT | GJ5: Konsumsi Pemerintah | GK5: Pembentukan Modal Tetap Bruto | GL5: Perubahan Inventori | GM5: Ekspor Barang (F.o.b) | GN5: Ekspor Jasa | GO5: Total Permintaan Akhir | GP5: Total Permintaan | GQ5: Impor Barang (c.i.f) | GR5: Impor Jasa | GS5: Adjustment (i.f) | GT5: Total Impor | GU5: Marjin Perdagangan Besar | GV5: Marjin Perdagangan Eceran | GW5: Biaya Pengangkutan | GX5: Total Marjin Perdagangan dan Biaya Pengangkutan | GY5: Total Pajak dikurang Subsidi atas Produk | GZ5: Output Domestik Harga Dasar | HA5: Total Penyediaan
B6: 1 | C6: Padi | D6: 21245051 | E6: 0 | F6: 0 | G6: 0 | H6: 0 | I6: 0 | J6: 0 | K6: 0 | L6: 0 | M6: 0 | N6: 0 | O6: 0 | P6: 0 | Q6: 0 | R6: 0 | S6: 0 | T6: 0 | U6: 0 | V6: 0 | W6: 0 | X6: 0 | Y6: 0 | Z6: 0 | AA6: 0 | AB6: 0 | AC6: 1341676 | AD6: 151780 | AE6: 411718 | AF6: 298480 | AG6: 0 | AH6: 0 | AI6: 0 | AJ6: 137336 | AK6: 244326 | AL6: 0 | AM6: 0 | AN6: 0 | AO6: 0 | AP6: 0 | AQ6: 0 | AR6: 0 | AS6: 0 | AT6: 0 | AU6: 0 | AV6: 0 | AW6: 0 | AX6: 0 | AY6: 0 | AZ6: 0 | BA6: 0 | BB6: 0 | BC6: 0 | BD6: 0 | BE6: 0 | BF6: 0 | BG6: 0 | BH6: 0 | BI6: 0 | BJ6: 0 | BK6: 0 | BL6: 0 | BM6: 0 | BN6: 246368653 | BO6: 0 | BP6: 0 | BQ6: 0 | BR6: 0 | BS6: 0 | BT6: 0 | BU6: 0 | BV6: 268 | BW6: 12157431 | BX6: 7066 | BY6: 0 | BZ6: 0 | CA6: 0 | CB6: 0 | CC6: 0 | CD6: 0 | CE6: 0 | CF6: 0 | CG6: 0 | CH6: 0 | CI6: 0 | CJ6: 0 | CK6: 0 | CL6: 0 | CM6: 0 | CN6: 0 | CO6: 0 | CP6: 0 | CQ6: 0 | CR6: 0 | CS6: 0 | CT6: 0 | CU6: 0 | CV6: 0 | CW6: 0 | CX6: 0 | CY6: 0 | CZ6: 0 | DA6: 0 | DB6: 0 | DC6: 0 | DD6: 0 | DE6: 0 | DF6: 0 | DG6: 0 | DH6: 0 | DI6: 0 | DJ6: 0 | DK6: 0 | DL6: 0 | DM6: 0 | DN6: 0 | DO6: 0 | DP6: 0 | DQ6: 0 | DR6: 0 | DS6: 0 | DT6: 0 | DU6: 0 | DV6: 0 | DW6: 0 | DX6: 0 | DY6: 0 | DZ6: 0 | EA6: 0 | EB6: 0 | EC6: 0 | ED6: 0 | EE6: 0 | EF6: 0 | EG6: 0 | EH6: 0 | EI6: 0 | EJ6: 0 | EK6: 0 | EL6: 0 | EM6: 0 | EN6: 0 | EO6: 0 | EP6: 0 | EQ6: 0 | ER6: 0 | ES6: 0 | ET6: 0 | EU6: 0 | EV6: 0 | EW6: 0 | EX6: 0 | EY6: 0 | EZ6: 0 | FA6: 0 | FB6: 0 | FC6: 2016032 | FD6: 0 | FE6: 199145 | FF6: 0 | FG6: 0 | FH6: 0 | FI6: 0 | FJ6: 0 | FK6: 0 | FL6: 0 | FM6: 0 | FN6: 0 | FO6: 0 | FP6: 0 | FQ6: 0 | FR6: 0 | FS6: 0 | FT6: 0 | FU6: 0 | FV6: 0 | FW6: 0 | FX6: 172292 | FY6: 0 | FZ6: 0 | GA6: 0 | GB6: 84810 | GC6: 0 | GD6: 0 | GE6: 0 | GF6: 0 | GG6: 284836064 | GH6: 0 | GI6: 0 | GJ6: 0 | GK6: 0 | GL6: 7607 | GM6: 5825 | GN6: 0 | GO6: 13432 | GP6: 284849496 | GQ6: 0 | GR6: 0 | GS6: 0 | GT6: 0 | GU6: 0 | GV6: 0 | GW6: 0 | GX6: 0 | GY6: 0 | GZ6: 284849496 | HA6: 284849496
B7: 2 | C7: Jagung | D7: 0 | E7: 3665242 | F7: 0 | G7: 0 | H7: 0 | I7: 0 | J7: 0 | K7: 0 | L7: 0 | M7: 0 | N7: 0 | O7: 0 | P7: 0 | Q7: 0 | R7: 0 | S7: 0 | T7: 0 | U7: 0 | V7: 0 | W7: 0 | X7: 0 | Y7: 0 | Z7: 0 | AA7: 0 | AB7: 0 | AC7: 471578 | AD7: 344979 | AE7: 1793691 | AF7: 49518 | AG7: 0 | AH7: 0 | AI7: 0 | AJ7: 429955 | AK7: 28831 | AL7: 9764 | AM7: 0 | AN7: 0 | AO7: 0 | AP7: 0 | AQ7: 0 | AR7: 0 | AS7: 0 | AT7: 0 | AU7: 0 | AV7: 0 | AW7: 0 | AX7: 0 | AY7: 0 | AZ7: 0 | BA7: 0 | BB7: 0 | BC7: 0 | BD7: 0 | BE7: 0 | BF7: 0 | BG7: 0 | BH7: 0 | BI7: 1663890 | BJ7: 0 | BK7: 0 | BL7: 4453732 | BM7: 108711 | BN7: 0 | BO7: 0 | BP7: 4287 | BQ7: 0 | BR7: 0 | BS7: 1530813 | BT7: 0 | BU7: 869010 | BV7: 8153031 | BW7: 26703807 | BX7: 80403 | BY7: 211357 | BZ7: 1224128 | CA7: 74663 | CB7: 0 | CC7: 0 | CD7: 0 | CE7: 0 | CF7: 0 | CG7: 0 | CH7: 0 | CI7: 0 | CJ7: 0 | CK7: 0 | CL7: 0 | CM7: 0 | CN7: 0 | CO7: 0 | CP7: 0 | CQ7: 0 | CR7: 0 | CS7: 0 | CT7: 0 | CU7: 0 | CV7: 0 | CW7: 0 | CX7: 0 | CY7: 0 | CZ7: 0 | DA7: 0 | DB7: 0 | DC7: 0 | DD7: 0 | DE7: 490 | DF7: 0 | DG7: 0 | DH7: 0 | DI7: 0 | DJ7: 0 | DK7: 0 | DL7: 0 | DM7: 0 | DN7: 0 | DO7: 0 | DP7: 0 | DQ7: 0 | DR7: 0 | DS7: 0 | DT7: 0 | DU7: 0 | DV7: 0 | DW7: 0 | DX7: 0 | DY7: 0 | DZ7: 0 | EA7: 0 | EB7: 0 | EC7: 0 | ED7: 0 | EE7: 0 | EF7: 0 | EG7: 0 | EH7: 0 | EI7: 0 | EJ7: 0 | EK7: 0 | EL7: 0 | EM7: 0 | EN7: 0 | EO7: 0 | EP7: 0 | EQ7: 0 | ER7: 0 | ES7: 0 | ET7: 0 | EU7: 0 | EV7: 0 | EW7: 0 | EX7: 0 | EY7: 0 | EZ7: 0 | FA7: 0 | FB7: 0 | FC7: 0 | FD7: 0 | FE7: 0 | FF7: 0 | FG7: 0 | FH7: 0 | FI7: 0 | FJ7: 0 | FK7: 246067 | FL7: 10258760 | FM7: 0 | FN7: 0 | FO7: 0 | FP7: 0 | FQ7: 0 | FR7: 0 | FS7: 0 | FT7: 0 | FU7: 0 | FV7: 0 | FW7: 0 | FX7: 146242 | FY7: 369 | FZ7: 5441 | GA7: 65 | GB7: 29472 | GC7: 294646 | GD7: 69057 | GE7: 0 | GF7: 94455 | GG7: 63016454 | GH7: 13875288 | GI7: 0 | GJ7: 0 | GK7: 0 | GL7: 2072894 | GM7: 211937 | GN7: 0 | GO7: 16160119 | GP7: 79176573 | GQ7: 0 | GR7: 0 | GS7: 0 | GT7: 0 | GU7: 0 | GV7: 0 | GW7: 0 | GX7: 0 | GY7: 0 | GZ7: 79176573 | HA7: 79176573
B8: 3 | C8: Ubi jalar | D8: 0 | E8: 0 | F8: 468533 | G8: 0 | H8: 0 | I8: 0 | J8: 0 | K8: 0 | L8: 0 | M8: 0 | N8: 0 | O8: 0 | P8: 0 | Q8: 0 | R8: 0 | S8: 0 | T8: 0 | U8: 0 | V8: 0 | W8: 0 | X8: 0 | Y8: 0 | Z8: 0 | AA8: 0 | AB8: 0 | AC8: 82536 | AD8: 44929 | AE8: 51317 | AF8: 6664 | AG8: 0 | AH8: 0 | AI8: 0 | AJ8: 0 | AK8: 0 | AL8: 0 | AM8: 0 | AN8: 0 | AO8: 0 | AP8: 0 | AQ8: 0 | AR8: 0 | AS8: 0 | AT8: 0 | AU8: 0 | AV8: 0 | AW8: 0 | AX8: 0 | AY8: 0 | AZ8: 0 | BA8: 0 | BB8: 0 | BC8: 0 | BD8: 0 | BE8: 0 | BF8: 0 | BG8: 0 | BH8: 6726 | BI8: 0 | BJ8: 0 | BK8: 0 | BL8: 383925 | BM8: 0 | BN8: 0 | BO8: 0 | BP8: 521 | BQ8: 0 | BR8: 0 | BS8: 0 | BT8: 0 | BU8: 0 | BV8: 1209103 | BW8: 36820 | BX8: 24 | BY8: 0 | BZ8: 0 | CA8: 0 | CB8: 0 | CC8: 0 | CD8: 0 | CE8: 0 | CF8: 0 | CG8: 0 | CH8: 0 | CI8: 0 | CJ8: 0 | CK8: 0 | CL8: 0 | CM8: 0 | CN8: 0 | CO8: 0 | CP8: 0 | CQ8: 0 | CR8: 0 | CS8: 0 | CT8: 0 | CU8: 0 | CV8: 0 | CW8: 0 | CX8: 0 | CY8: 0 | CZ8: 0 | DA8: 0 | DB8: 0 | DC8: 0 | DD8: 0 | DE8: 156 | DF8: 0 | DG8: 0 | DH8: 0 | DI8: 0 | DJ8: 0 | DK8: 0 | DL8: 0 | DM8: 0 | DN8: 0 | DO8: 0 | DP8: 0 | DQ8: 0 | DR8: 0 | DS8: 0 | DT8: 0 | DU8: 0 | DV8: 0 | DW8: 0 | DX8: 0 | DY8: 0 | DZ8: 0 | EA8: 0 | EB8: 0 | EC8: 0 | ED8: 0 | EE8: 0 | EF8: 0 | EG8: 0 | EH8: 0 | EI8: 0 | EJ8: 0 | EK8: 0 | EL8: 0 | EM8: 0 | EN8: 0 | EO8: 0 | EP8: 0 | EQ8: 0 | ER8: 0 | ES8: 0 | ET8: 0 | EU8: 0 | EV8: 0 | EW8: 0 | EX8: 0 | EY8: 0 | EZ8: 0 | FA8: 0 | FB8: 0 | FC8: 0 | FD8: 0 | FE8: 0 | FF8: 0 | FG8: 0 | FH8: 0 | FI8: 0 | FJ8: 0 | FK8: 47797 | FL8: 561366 | FM8: 0 | FN8: 0 | FO8: 0 | FP8: 0 | FQ8: 0 | FR8: 0 | FS8: 0 | FT8: 0 | FU8: 0 | FV8: 0 | FW8: 0 | FX8: 3556 | FY8: 212 | FZ8: 103766 | GA8: 27 | GB8: 3520 | GC8: 45938 | GD8: 193077 | GE8: 0 | GF8: 1258 | GG8: 3251771 | GH8: 5993774 | GI8: 0 | GJ8: 0 | GK8: 0 | GL8: -243255 | GM8: 132618 | GN8: 0 | GO8: 5883137 | GP8: 9134908 | GQ8: 0 | GR8: 0 | GS8: 0 | GT8: 0 | GU8: 0 | GV8: 0 | GW8: 0 | GX8: 0 | GY8: 0 | GZ8: 9134908 | HA8: 9134908
B9: 4 | C9: Ubi kayu | D9: 0 | E9: 0 | F9: 0 | G9: 3077480 | H9: 0 | I9: 0 | J9: 0 | K9: 0 | L9: 0 | M9: 0 | N9: 0 | O9: 0 | P9: 0 | Q9: 0 | R9: 0 | S9: 0 | T9: 0 | U9: 0 | V9: 0 | W9: 0 | X9: 0 | Y9: 0 | Z9: 0 | AA9: 0 | AB9: 0 | AC9: 341850 | AD9: 45229 | AE9: 264355 | AF9: 17148 | AG9: 252 | AH9: 0 | AI9: 0 | AJ9: 67657 | AK9: 355 | AL9: 146 | AM9: 0 | AN9: 0 | AO9: 0 | AP9: 0 | AQ9: 0 | AR9: 0 | AS9: 0 | AT9: 0 | AU9: 0 | AV9: 0 | AW9: 0 | AX9: 0 | AY9: 0 | AZ9: 0 | BA9: 0 | BB9: 0 | BC9: 0 | BD9: 0 | BE9: 0 | BF9: 0 | BG9: 0 | BH9: 0 | BI9: 0 | BJ9: 0 | BK9: 0 | BL9: 7954294 | BM9: 217568 | BN9: 0 | BO9: 0 | BP9: 88042 | BQ9: 0 | BR9: 0 | BS9: 0 | BT9: 0 | BU9: 0 | BV9: 14643278 | BW9: 1725629 | BX9: 2214 | BY9: 0 | BZ9: 0 | CA9: 0 | CB9: 0 | CC9: 0 | CD9: 0 | CE9: 0 | CF9: 0 | CG9: 0 | CH9: 0 | CI9: 0 | CJ9: 0 | CK9: 0 | CL9: 0 | CM9: 0 | CN9: 0 | CO9: 0 | CP9: 0 | CQ9: 0 | CR9: 0 | CS9: 0 | CT9: 0 | CU9: 0 | CV9: 0 | CW9: 0 | CX9: 0 | CY9: 0 | CZ9: 0 | DA9: 0 | DB9: 0 | DC9: 0 | DD9: 0 | DE9: 310 | DF9: 0 | DG9: 0 | DH9: 0 | DI9: 0 | DJ9: 0 | DK9: 0 | DL9: 0 | DM9: 0 | DN9: 0 | DO9: 0 | DP9: 0 | DQ9: 0 | DR9: 0 | DS9: 0 | DT9: 0 | DU9: 0 | DV9: 0 | DW9: 0 | DX9: 0 | DY9: 0 | DZ9: 0 | EA9: 0 | EB9: 0 | EC9: 0 | ED9: 0 | EE9: 0 | EF9: 0 | EG9: 0 | EH9: 0 | EI9: 0 | EJ9: 0 | EK9: 0 | EL9: 0 | EM9: 0 | EN9: 0 | EO9: 0 | EP9: 0 | EQ9: 0 | ER9: 0 | ES9: 0 | ET9: 0 | EU9: 0 | EV9: 0 | EW9: 0 | EX9: 0 | EY9: 0 | EZ9: 0 | FA9: 0 | FB9: 0 | FC9: 0 | FD9: 0 | FE9: 0 | FF9: 0 | FG9: 0 | FH9: 0 | FI9: 0 | FJ9: 0 | FK9: 174799 | FL9: 12565646 | FM9: 0 | FN9: 0 | FO9: 0 | FP9: 0 | FQ9: 0 | FR9: 0 | FS9: 0 | FT9: 0 | FU9: 0 | FV9: 0 | FW9: 0 | FX9: 1147 | FY9: 117 | FZ9: 41160 | GA9: 54 | GB9: 12906 | GC9: 36732 | GD9: 111997 | GE9: 0 | GF9: 893 | GG9: 41391258 | GH9: 12645464 | GI9: 0 | GJ9: 0 | GK9: 0 | GL9: -20157 | GM9: 114368 | GN9: 0 | GO9: 12739675 | GP9: 54130933 | GQ9: 0 | GR9: 0 | GS9: 0 | GT9: 0 | GU9: 0 | GV9: 0 | GW9: 0 | GX9: 0 | GY9: 0 | GZ9: 54130933 | HA9: 54130933
B10: 5 | C10: Umbi-umbian lainnya | D10: 0 | E10: 0 | F10: 0 | G10: 0 | H10: 129416 | I10: 0 | J10: 0 | K10: 0 | L10: 0 | M10: 0 | N10: 0 | O10: 0 | P10: 0 | Q10: 0 | R10: 0 | S10: 0 | T10: 0 | U10: 0 | V10: 0 | W10: 0 | X10: 0 | Y10: 0 | Z10: 0 | AA10: 0 | AB10: 0 | AC10: 142850 | AD10: 21055 | AE10: 75 | AF10: 210 | AG10: 0 | AH10: 0 | AI10: 0 | AJ10: 0 | AK10: 0 | AL10: 0 | AM10: 0 | AN10: 0 | AO10: 0 | AP10: 0 | AQ10: 0 | AR10: 0 | AS10: 0 | AT10: 0 | AU10: 0 | AV10: 0 | AW10: 0 | AX10: 0 | AY10: 0 | AZ10: 0 | BA10: 0 | BB10: 0 | BC10: 0 | BD10: 0 | BE10: 0 | BF10: 0 | BG10: 0 | BH10: 0 | BI10: 0 | BJ10: 0 | BK10: 0 | BL10: 29010 | BM10: 0 | BN10: 0 | BO10: 0 | BP10: 0 | BQ10: 0 | BR10: 121 | BS10: 0 | BT10: 0 | BU10: 0 | BV10: 797363 | BW10: 67756 | BX10: 32 | BY10: 381 | BZ10: 0 | CA10: 0 | CB10: 0 | CC10: 0 | CD10: 0 | CE10: 0 | CF10: 0 | CG10: 0 | CH10: 0 | CI10: 0 | CJ10: 0 | CK10: 0 | CL10: 0 | CM10: 0 | CN10: 0 | CO10: 0 | CP10: 0 | CQ10: 0 | CR10: 0 | CS10: 0 | CT10: 0 | CU10: 0 | CV10: 0 | CW10: 0 | CX10: 0 | CY10: 0 | CZ10: 0 | DA10: 0 | DB10: 0 | DC10: 0 | DD10: 0 | DE10: 82 | DF10: 0 | DG10: 0 | DH10: 0 | DI10: 0 | DJ10: 0 | DK10: 0 | DL10: 0 | DM10: 0 | DN10: 0 | DO10: 0 | DP10: 0 | DQ10: 0 | DR10: 0 | DS10: 0 | DT10: 0 | DU10: 0 | DV10: 0 | DW10: 0 | DX10: 0 | DY10: 0 | DZ10: 0 | EA10: 0 | EB10: 0 | EC10: 0 | ED10: 0 | EE10: 0 | EF10: 0 | EG10: 0 | EH10: 0 | EI10: 0 | EJ10: 0 | EK10: 0 | EL10: 0 | EM10: 0 | EN10: 0 | EO10: 0 | EP10: 0 | EQ10: 0 | ER10: 0 | ES10: 0 | ET10: 0 | EU10: 0 | EV10: 0 | EW10: 0 | EX10: 0 | EY10: 0 | EZ10: 0 | FA10: 0 | FB10: 0 | FC10: 0 | FD10: 0 | FE10: 0 | FF10: 0 | FG10: 0 | FH10: 0 | FI10: 0 | FJ10: 0 | FK10: 68263 | FL10: 206739 | FM10: 0 | FN10: 0 | FO10: 0 | FP10: 0 | FQ10: 0 | FR10: 0 | FS10: 0 | FT10: 0 | FU10: 0 | FV10: 0 | FW10: 0 | FX10: 72496 | FY10: 3762 | FZ10: 231177 | GA10: 5450 | GB10: 2890 | GC10: 17498 | GD10: 49729 | GE10: 0 | GF10: 10955 | GG10: 1857310 | GH10: 1172358 | GI10: 0 | GJ10: 0 | GK10: 0 | GL10: 14 | GM10: 315024 | GN10: 0 | GO10: 1487396 | GP10: 3344706 | GQ10: 0 | GR10: 0 | GS10: 0 | GT10: 0 | GU10: 0 | GV10: 0 | GW10: 0 | GX10: 0 | GY10: 0 | GZ10: 3344706 | HA10: 3344706
B11: 6 | C11: Kacang tanah | D11: 0 | E11: 0 | F11: 0 | G11: 0 | H11: 0 | I11: 266807 | J11: 0 | K11: 0 | L11: 0 | M11: 0 | N11: 0 | O11: 0 | P11: 0 | Q11: 0 | R11: 0 | S11: 0 | T11: 0 | U11: 0 | V11: 0 | W11: 0 | X11: 0 | Y11: 0 | Z11: 0 | AA11: 0 | AB11: 0 | AC11: 31100 | AD11: 892 | AE11: 14000 | AF11: 2215 | AG11: 0 | AH11: 0 | AI11: 0 | AJ11: 0 | AK11: 0 | AL11: 0 | AM11: 0 | AN11: 0 | AO11: 0 | AP11: 0 | AQ11: 0 | AR11: 0 | AS11: 0 | AT11: 0 | AU11: 0 | AV11: 0 | AW11: 0 | AX11: 0 | AY11: 0 | AZ11: 0 | BA11: 0 | BB11: 0 | BC11: 0 | BD11: 0 | BE11: 0 | BF11: 0 | BG11: 0 | BH11: 432428 | BI11: 16235 | BJ11: 0 | BK11: 0 | BL11: 491098 | BM11: 0 | BN11: 0 | BO11: 0 | BP11: 0 | BQ11: 0 | BR11: 0 | BS11: 334 | BT11: 0 | BU11: 0 | BV11: 2351321 | BW11: 389370 | BX11: 0 | BY11: 25356 | BZ11: 0 | CA11: 0 | CB11: 0 | CC11: 0 | CD11: 0 | CE11: 0 | CF11: 0 | CG11: 0 | CH11: 0 | CI11: 0 | CJ11: 0 | CK11: 0 | CL11: 0 | CM11: 0 | CN11: 0 | CO11: 0 | CP11: 0 | CQ11: 0 | CR11: 0 | CS11: 0 | CT11: 0 | CU11: 0 | CV11: 0 | CW11: 0 | CX11: 0 | CY11: 0 | CZ11: 0 | DA11: 0 | DB11: 0 | DC11: 0 | DD11: 760 | DE11: 47 | DF11: 0 | DG11: 0 | DH11: 0 | DI11: 0 | DJ11: 0 | DK11: 0 | DL11: 0 | DM11: 0 | DN11: 0 | DO11: 0 | DP11: 0 | DQ11: 0 | DR11: 0 | DS11: 0 | DT11: 0 | DU11: 0 | DV11: 0 | DW11: 0 | DX11: 0 | DY11: 0 | DZ11: 0 | EA11: 0 | EB11: 0 | EC11: 0 | ED11: 0 | EE11: 0 | EF11: 0 | EG11: 0 | EH11: 0 | EI11: 0 | EJ11: 0 | EK11: 0 | EL11: 0 | EM11: 0 | EN11: 0 | EO11: 0 | EP11: 0 | EQ11: 0 | ER11: 0 | ES11: 0 | ET11: 0 | EU11: 0 | EV11: 0 | EW11: 0 | EX11: 0 | EY11: 0 | EZ11: 0 | FA11: 0 | FB11: 0 | FC11: 0 | FD11: 0 | FE11: 0 | FF11: 0 | FG11: 0 | FH11: 0 | FI11: 0 | FJ11: 0 | FK11: 17522 | FL11: 385286 | FM11: 0 | FN11: 0 | FO11: 0 | FP11: 0 | FQ11: 0 | FR11: 0 | FS11: 0 | FT11: 0 | FU11: 0 | FV11: 0 | FW11: 0 | FX11: 35905 | FY11: 2219 | FZ11: 4572 | GA11: 3452 | GB11: 8490 | GC11: 18544 | GD11: 23257 | GE11: 0 | GF11: 29893 | GG11: 4551103 | GH11: 2535612 | GI11: 0 | GJ11: 0 | GK11: 0 | GL11: 52149 | GM11: 61767 | GN11: 0 | GO11: 2649528 | GP11: 7200631 | GQ11: 0 | GR11: 0 | GS11: 0 | GT11: 0 | GU11: 0 | GV11: 0 | GW11: 0 | GX11: 0 | GY11: 0 | GZ11: 7200631 | HA11: 7200631
B12: 7 | C12: Kedelai | D12: 0 | E12: 0 | F12: 0 | G12: 0 | H12: 0 | I12: 0 | J12: 42610 | K12: 0 | L12: 0 | M12: 0 | N12: 0 | O12: 0 | P12: 0 | Q12: 0 | R12: 0 | S12: 0 | T12: 0 | U12: 0 | V12: 0 | W12: 0 | X12: 0 | Y12: 0 | Z12: 0 | AA12: 0 | AB12: 0 | AC12: 3372 | AD12: 22 | AE12: 226 | AF12: 216 | AG12: 0 | AH12: 0 | AI12: 0 | AJ12: 0 | AK12: 0 | AL12: 0 | AM12: 0 | AN12: 0 | AO12: 0 | AP12: 0 | AQ12: 0 | AR12: 0 | AS12: 0 | AT12: 0 | AU12: 0 | AV12: 0 | AW12: 0 | AX12: 0 | AY12: 0 | AZ12: 0 | BA12: 0 | BB12: 0 | BC12: 0 | BD12: 0 | BE12: 0 | BF12: 0 | BG12: 0 | BH12: 319922 | BI12: 1220 | BJ12: 0 | BK12: 0 | BL12: 73201 | BM12: 0 | BN12: 0 | BO12: 0 | BP12: 0 | BQ12: 0 | BR12: 0 | BS12: 11 | BT12: 0 | BU12: 3546185 | BV12: 3276 | BW12: 855 | BX12: 350 | BY12: 12428 | BZ12: 0 | CA12: 0 | CB12: 0 | CC12: 0 | CD12: 0 | CE12: 0 | CF12: 0 | CG12: 0 | CH12: 0 | CI12: 0 | CJ12: 0 | CK12: 0 | CL12: 0 | CM12: 0 | CN12: 0 | CO12: 0 | CP12: 0 | CQ12: 0 | CR12: 0 | CS12: 0 | CT12: 0 | CU12: 0 | CV12: 0 | CW12: 0 | CX12: 0 | CY12: 0 | CZ12: 0 | DA12: 0 | DB12: 0 | DC12: 0 | DD12: 22 | DE12: 6 | DF12: 0 | DG12: 0 | DH12: 0 | DI12: 0 | DJ12: 0 | DK12: 0 | DL12: 0 | DM12: 0 | DN12: 0 | DO12: 0 | DP12: 0 | DQ12: 0 | DR12: 0 | DS12: 0 | DT12: 0 | DU12: 0 | DV12: 0 | DW12: 0 | DX12: 0 | DY12: 0 | DZ12: 0 | EA12: 0 | EB12: 0 | EC12: 0 | ED12: 0 | EE12: 0 | EF12: 0 | EG12: 0 | EH12: 0 | EI12: 0 | EJ12: 0 | EK12: 0 | EL12: 0 | EM12: 0 | EN12: 0 | EO12: 0 | EP12: 0 | EQ12: 0 | ER12: 0 | ES12: 0 | ET12: 0 | EU12: 0 | EV12: 0 | EW12: 0 | EX12: 0 | EY12: 0 | EZ12: 0 | FA12: 0 | FB12: 0 | FC12: 0 | FD12: 0 | FE12: 0 | FF12: 0 | FG12: 0 | FH12: 0 | FI12: 0 | FJ12: 0 | FK12: 11 | FL12: 1628 | FM12: 0 | FN12: 0 | FO12: 0 | FP12: 0 | FQ12: 0 | FR12: 0 | FS12: 0 | FT12: 0 | FU12: 0 | FV12: 0 | FW12: 0 | FX12: 7762 | FY12: 22 | FZ12: 429 | GA12: 19 | GB12: 818 | GC12: 908 | GD12: 825 | GE12: 0 | GF12: 3841 | GG12: 4020185 | GH12: 175006 | GI12: 0 | GJ12: 0 | GK12: 0 | GL12: 81450 | GM12: 7135 | GN12: 0 | GO12: 263591 | GP12: 4283776 | GQ12: 0 | GR12: 0 | GS12: 0 | GT12: 0 | GU12: 0 | GV12: 0 | GW12: 0 | GX12: 0 | GY12: 0 | GZ12: 4283776 | HA12: 4283776
B13: 8 | C13: Kacang-kacangan Lainnya | D13: 0 | E13: 0 | F13: 0 | G13: 0 | H13: 0 | I13: 0 | J13: 0 | K13: 525023 | L13: 0 | M13: 0 | N13: 0 | O13: 0 | P13: 0 | Q13: 0 | R13: 0 | S13: 0 | T13: 0 | U13: 0 | V13: 0 | W13: 0 | X13: 0 | Y13: 0 | Z13: 0 | AA13: 0 | AB13: 0 | AC13: 9389 | AD13: 280 | AE13: 5610 | AF13: 1457 | AG13: 0 | AH13: 0 | AI13: 0 | AJ13: 0 | AK13: 0 | AL13: 0 | AM13: 0 | AN13: 0 | AO13: 0 | AP13: 0 | AQ13: 0 | AR13: 0 | AS13: 0 | AT13: 0 | AU13: 0 | AV13: 0 | AW13: 0 | AX13: 0 | AY13: 0 | AZ13: 0 | BA13: 0 | BB13: 0 | BC13: 0 | BD13: 0 | BE13: 0 | BF13: 0 | BG13: 0 | BH13: 0 | BI13: 57 | BJ13: 0 | BK13: 0 | BL13: 9331 | BM13: 0 | BN13: 0 | BO13: 48401 | BP13: 0 | BQ13: 0 | BR13: 0 | BS13: 78 | BT13: 0 | BU13: 57879 | BV13: 215944 | BW13: 37946 | BX13: 23 | BY13: 182523 | BZ13: 0 | CA13: 0 | CB13: 0 | CC13: 0 | CD13: 0 | CE13: 0 | CF13: 0 | CG13: 0 | CH13: 0 | CI13: 0 | CJ13: 0 | CK13: 0 | CL13: 0 | CM13: 0 | CN13: 0 | CO13: 0 | CP13: 0 | CQ13: 0 | CR13: 0 | CS13: 0 | CT13: 0 | CU13: 0 | CV13: 0 | CW13: 0 | CX13: 0 | CY13: 0 | CZ13: 0 | DA13: 0 | DB13: 0 | DC13: 0 | DD13: 595 | DE13: 9 | DF13: 0 | DG13: 0 | DH13: 0 | DI13: 0 | DJ13: 0 | DK13: 0 | DL13: 0 | DM13: 0 | DN13: 0 | DO13: 0 | DP13: 0 | DQ13: 0 | DR13: 0 | DS13: 0 | DT13: 0 | DU13: 0 | DV13: 0 | DW13: 0 | DX13: 0 | DY13: 0 | DZ13: 0 | EA13: 0 | EB13: 0 | EC13: 0 | ED13: 0 | EE13: 0 | EF13: 0 | EG13: 0 | EH13: 0 | EI13: 0 | EJ13: 0 | EK13: 0 | EL13: 0 | EM13: 0 | EN13: 0 | EO13: 0 | EP13: 0 | EQ13: 0 | ER13: 0 | ES13: 0 | ET13: 0 | EU13: 0 | EV13: 0 | EW13: 0 | EX13: 0 | EY13: 0 | EZ13: 0 | FA13: 0 | FB13: 0 | FC13: 0 | FD13: 0 | FE13: 0 | FF13: 0 | FG13: 0 | FH13: 0 | FI13: 0 | FJ13: 0 | FK13: 3345 | FL13: 70896 | FM13: 0 | FN13: 0 | FO13: 0 | FP13: 0 | FQ13: 0 | FR13: 0 | FS13: 0 | FT13: 0 | FU13: 0 | FV13: 0 | FW13: 0 | FX13: 0 | FY13: 1196 | FZ13: 1388 | GA13: 356 | GB13: 14103 | GC13: 28298 | GD13: 14170 | GE13: 0 | GF13: 67025 | GG13: 1295322 | GH13: 11145361 | GI13: 0 | GJ13: 0 | GK13: 0 | GL13: 9 | GM13: 32616 | GN13: 0 | GO13: 11177986 | GP13: 12473308 | GQ13: 0 | GR13: 0 | GS13: 0 | GT13: 0 | GU13: 0 | GV13: 0 | GW13: 0 | GX13: 0 | GY13: 0 | GZ13: 12473308 | HA13: 12473308
B14: 9 | C14: Padi-padian dan Bahan Makanan Lainnya | D14: 0 | E14: 0 | F14: 0 | G14: 0 | H14: 0 | I14: 0 | J14: 0 | K14: 0 | L14: 20247 | M14: 0 | N14: 0 | O14: 0 | P14: 0 | Q14: 0 | R14: 0 | S14: 0 | T14: 0 | U14: 0 | V14: 0 | W14: 0 | X14: 0 | Y14: 0 | Z14: 0 | AA14: 0 | AB14: 0 | AC14: 0 | AD14: 0 | AE14: 41 | AF14: 1342 | AG14: 0 | AH14: 0 | AI14: 0 | AJ14: 0 | AK14: 0 | AL14: 0 | AM14: 0 | AN14: 0 | AO14: 0 | AP14: 0 | AQ14: 0 | AR14: 0 | AS14: 0 | AT14: 0 | AU14: 0 | AV14: 0 | AW14: 0 | AX14: 0 | AY14: 0 | AZ14: 0 | BA14: 0 | BB14: 0 | BC14: 0 | BD14: 0 | BE14: 0 | BF14: 0 | BG14: 0 | BH14: 0 | BI14: 59512 | BJ14: 0 | BK14: 0 | BL14: 22241 | BM14: 82060 | BN14: 0 | BO14: 0 | BP14: 718 | BQ14: 167 | BR14: 0 | BS14: 0 | BT14: 0 | BU14: 0 | BV14: 1238 | BW14: 118 | BX14: 152762 | BY14: 27 | BZ14: 0 | CA14: 0 | CB14: 0 | CC14: 0 | CD14: 0 | CE14: 0 | CF14: 0 | CG14: 0 | CH14: 0 | CI14: 0 | CJ14: 0 | CK14: 0 | CL14: 0 | CM14: 0 | CN14: 0 | CO14: 0 | CP14: 0 | CQ14: 0 | CR14: 0 | CS14: 0 | CT14: 0 | CU14: 0 | CV14: 0 | CW14: 0 | CX14: 0 | CY14: 0 | CZ14: 0 | DA14: 0 | DB14: 0 | DC14: 133 | DD14: 211 | DE14: 0 | DF14: 0 | DG14: 0 | DH14: 0 | DI14: 0 | DJ14: 0 | DK14: 0 | DL14: 0 | DM14: 0 | DN14: 0 | DO14: 0 | DP14: 0 | DQ14: 0 | DR14: 0 | DS14: 0 | DT14: 0 | DU14: 0 | DV14: 0 | DW14: 0 | DX14: 0 | DY14: 0 | DZ14: 0 | EA14: 0 | EB14: 0 | EC14: 0 | ED14: 0 | EE14: 0 | EF14: 0 | EG14: 0 | EH14: 0 | EI14: 0 | EJ14: 0 | EK14: 0 | EL14: 0 | EM14: 0 | EN14: 0 | EO14: 0 | EP14: 0 | EQ14: 0 | ER14: 0 | ES14: 0 | ET14: 0 | EU14: 0 | EV14: 0 | EW14: 0 | EX14: 0 | EY14: 0 | EZ14: 0 | FA14: 0 | FB14: 0 | FC14: 0 | FD14: 0 | FE14: 0 | FF14: 0 | FG14: 0 | FH14: 0 | FI14: 0 | FJ14: 0 | FK14: 3508 | FL14: 5419 | FM14: 0 | FN14: 0 | FO14: 0 | FP14: 0 | FQ14: 0 | FR14: 0 | FS14: 0 | FT14: 0 | FU14: 0 | FV14: 0 | FW14: 0 | FX14: 0 | FY14: 197 | FZ14: 224 | GA14: 372 | GB14: 968 | GC14: 3656 | GD14: 208 | GE14: 0 | GF14: 4466 | GG14: 359835 | GH14: 1633 | GI14: 0 | GJ14: 0 | GK14: 0 | GL14: 1301 | GM14: 40444 | GN14: 0 | GO14: 43378 | GP14: 403213 | GQ14: 0 | GR14: 0 | GS14: 0 | GT14: 0 | GU14: 0 | GV14: 0 | GW14: 0 | GX14: 0 | GY14: 0 | GZ14: 403213 | HA14: 403213
B15: 10 | C15: Sayur-sayuran | D15: 0 | E15: 0 | F15: 0 | G15: 0 | H15: 0 | I15: 0 | J15: 0 | K15: 0 | L15: 0 | M15: 6843319 | N15: 0 | O15: 0 | P15: 0 | Q15: 0 | R15: 0 | S15: 0 | T15: 0 | U15: 0 | V15: 0 | W15: 0 | X15: 0 | Y15: 0 | Z15: 0 | AA15: 0 | AB15: 0 | AC15: 229245 | AD15: 5 | AE15: 476 | AF15: 137035 | AG15: 0 | AH15: 0 | AI15: 0 | AJ15: 0 | AK15: 0 | AL15: 0 | AM15: 0 | AN15: 0 | AO15: 0 | AP15: 0 | AQ15: 0 | AR15: 0 | AS15: 0 | AT15: 0 | AU15: 0 | AV15: 0 | AW15: 0 | AX15: 0 | AY15: 0 | AZ15: 0 | BA15: 0 | BB15: 0 | BC15: 0 | BD15: 0 | BE15: 0 | BF15: 5792 | BG15: 8363 | BH15: 1650955 | BI15: 0 | BJ15: 0 | BK15: 0 | BL15: 11226 | BM15: 0 | BN15: 0 | BO15: 0 | BP15: 0 | BQ15: 5092 | BR15: 3804988 | BS15: 0 | BT15: 0 | BU15: 62246 | BV15: 13113067 | BW15: 59691 | BX15: 10771 | BY15: 12149 | BZ15: 0 | CA15: 0 | CB15: 0 | CC15: 0 | CD15: 0 | CE15: 0 | CF15: 0 | CG15: 0 | CH15: 0 | CI15: 0 | CJ15: 0 | CK15: 0 | CL15: 0 | CM15: 0 | CN15: 0 | CO15: 0 | CP15: 0 | CQ15: 0 | CR15: 0 | CS15: 0 | CT15: 0 | CU15: 0 | CV15: 0 | CW15: 0 | CX15: 0 | CY15: 0 | CZ15: 0 | DA15: 0 | DB15: 0 | DC15: 0 | DD15: 164500 | DE15: 53149 | DF15: 0 | DG15: 0 | DH15: 0 | DI15: 0 | DJ15: 0 | DK15: 0 | DL15: 0 | DM15: 0 | DN15: 0 | DO15: 0 | DP15: 0 | DQ15: 0 | DR15: 0 | DS15: 0 | DT15: 0 | DU15: 0 | DV15: 0 | DW15: 0 | DX15: 0 | DY15: 0 | DZ15: 0 | EA15: 0 | EB15: 0 | EC15: 0 | ED15: 0 | EE15: 0 | EF15: 0 | EG15: 0 | EH15: 0 | EI15: 0 | EJ15: 0 | EK15: 0 | EL15: 0 | EM15: 0 | EN15: 0 | EO15: 0 | EP15: 0 | EQ15: 0 | ER15: 0 | ES15: 0 | ET15: 0 | EU15: 0 | EV15: 0 | EW15: 0 | EX15: 0 | EY15: 0 | EZ15: 0 | FA15: 0 | FB15: 0 | FC15: 0 | FD15: 0 | FE15: 0 | FF15: 0 | FG15: 0 | FH15: 0 | FI15: 0 | FJ15: 0 | FK15: 2901779 | FL15: 20320926 | FM15: 0 | FN15: 0 | FO15: 0 | FP15: 0 | FQ15: 0 | FR15: 0 | FS15: 0 | FT15: 0 | FU15: 0 | FV15: 0 | FW15: 0 | FX15: 526375 | FY15: 18829 | FZ15: 139253 | GA15: 27456 | GB15: 67348 | GC15: 860140 | GD15: 823520 | GE15: 0 | GF15: 115871 | GG15: 51973566 | GH15: 131755725 | GI15: 0 | GJ15: 0 | GK15: 794955 | GL15: -165471 | GM15: 1257072 | GN15: 0 | GO15: 133642281 | GP15: 185615847 | GQ15: 0 | GR15: 0 | GS15: 0 | GT15: 0 | GU15: 0 | GV15: 0 | GW15: 0 | GX15: 0 | GY15: 0 | GZ15: 185615847 | HA15: 185615847
B16: 11 | C16: Tanaman Hias dan Holtikultura Lainnya | D16: 0 | E16: 0 | F16: 0 | G16: 0 | H16: 0 | I16: 0 | J16: 0 | K16: 0 | L16: 0 | M16: 0 | N16: 200309 | O16: 0 | P16: 0 | Q16: 0 | R16: 0 | S16: 0 | T16: 0 | U16: 0 | V16: 0 | W16: 0 | X16: 0 | Y16: 0 | Z16: 0 | AA16: 0 | AB16: 0 | AC16: 718743 | AD16: 33181 | AE16: 201484 | AF16: 39756 | AG16: 0 | AH16: 0 | AI16: 0 | AJ16: 182190 | AK16: 0 | AL16: 0 | AM16: 0 | AN16: 0 | AO16: 0 | AP16: 0 | AQ16: 0 | AR16: 0 | AS16: 0 | AT16: 0 | AU16: 0 | AV16: 0 | AW16: 0 | AX16: 0 | AY16: 0 | AZ16: 0 | BA16: 0 | BB16: 0 | BC16: 0 | BD16: 0 | BE16: 0 | BF16: 0 | BG16: 0 | BH16: 0 | BI16: 0 | BJ16: 0 | BK16: 0 | BL16: 0 | BM16: 0 | BN16: 0 | BO16: 0 | BP16: 0 | BQ16: 0 | BR16: 0 | BS16: 0 | BT16: 922709 | BU16: 0 | BV16: 0 | BW16: 103057 | BX16: 0 | BY16: 1526 | BZ16: 127 | CA16: 0 | CB16: 0 | CC16: 0 | CD16: 0 | CE16: 0 | CF16: 0 | CG16: 0 | CH16: 0 | CI16: 0 | CJ16: 0 | CK16: 0 | CL16: 0 | CM16: 0 | CN16: 0 | CO16: 0 | CP16: 0 | CQ16: 0 | CR16: 0 | CS16: 0 | CT16: 0 | CU16: 0 | CV16: 0 | CW16: 0 | CX16: 0 | CY16: 0 | CZ16: 0 | DA16: 0 | DB16: 0 | DC16: 3083 | DD16: 301397 | DE16: 30646 | DF16: 0 | DG16: 0 | DH16: 0 | DI16: 0 | DJ16: 0 | DK16: 0 | DL16: 0 | DM16: 0 | DN16: 0 | DO16: 0 | DP16: 0 | DQ16: 0 | DR16: 0 | DS16: 0 | DT16: 0 | DU16: 0 | DV16: 0 | DW16: 0 | DX16: 0 | DY16: 0 | DZ16: 0 | EA16: 0 | EB16: 0 | EC16: 0 | ED16: 0 | EE16: 0 | EF16: 0 | EG16: 0 | EH16: 0 | EI16: 0 | EJ16: 0 | EK16: 0 | EL16: 0 | EM16: 0 | EN16: 0 | EO16: 0 | EP16: 381 | EQ16: 0 | ER16: 0 | ES16: 0 | ET16: 0 | EU16: 3560 | EV16: 645163 | EW16: 178894 | EX16: 0 | EY16: 36112 | EZ16: 96589 | FA16: 0 | FB16: 0 | FC16: 0 | FD16: 0 | FE16: 0 | FF16: 0 | FG16: 0 | FH16: 0 | FI16: 0 | FJ16: 0 | FK16: 0 | FL16: 0 | FM16: 0 | FN16: 0 | FO16: 0 | FP16: 0 | FQ16: 0 | FR16: 0 | FS16: 0 | FT16: 0 | FU16: 0 | FV16: 0 | FW16: 0 | FX16: 113552 | FY16: 1260 | FZ16: 822 | GA16: 192 | GB16: 16609 | GC16: 6118 | GD16: 590980 | GE16: 0 | GF16: 21230 | GG16: 4449670 | GH16: 963439 | GI16: 0 | GJ16: 0 | GK16: 124505 | GL16: 30099 | GM16: 427869 | GN16: 0 | GO16: 1545912 | GP16: 5995582 | GQ16: 0 | GR16: 0 | GS16: 0 | GT16: 0 | GU16: 0 | GV16: 0 | GW16: 0 | GX16: 0 | GY16: 0 | GZ16: 5995582 | HA16: 5995582
B17: 12 | C17: Tebu | D17: 0 | E17: 0 | F17: 0 | G17: 0 | H17: 0 | I17: 0 | J17: 0 | K17: 0 | L17: 0 | M17: 0 | N17: 0 | O17: 1683110 | P17: 0 | Q17: 0 | R17: 0 | S17: 0 | T17: 0 | U17: 0 | V17: 0 | W17: 0 | X17: 0 | Y17: 0 | Z17: 0 | AA17: 0 | AB17: 0 | AC17: 656480 | AD17: 47375 | AE17: 40 | AF17: 0 | AG17: 0 | AH17: 0 | AI17: 0 | AJ17: 0 | AK17: 0 | AL17: 0 | AM17: 0 | AN17: 0 | AO17: 0 | AP17: 0 | AQ17: 0 | AR17: 0 | AS17: 0 | AT17: 0 | AU17: 0 | AV17: 0 | AW17: 0 | AX17: 0 | AY17: 0 | AZ17: 0 | BA17: 0 | BB17: 0 | BC17: 0 | BD17: 0 | BE17: 0 | BF17: 0 | BG17: 0 | BH17: 0 | BI17: 0 | BJ17: 0 | BK17: 3286 | BL17: 0 | BM17: 0 | BN17: 0 | BO17: 0 | BP17: 17584855 | BQ17: 0 | BR17: 0 | BS17: 0 | BT17: 9572 | BU17: 0 | BV17: 311 | BW17: 0 | BX17: 31 | BY17: 19777 | BZ17: 0 | CA17: 0 | CB17: 0 | CC17: 0 | CD17: 0 | CE17: 0 | CF17: 0 | CG17: 0 | CH17: 0 | CI17: 0 | CJ17: 0 | CK17: 0 | CL17: 0 | CM17: 0 | CN17: 0 | CO17: 0 | CP17: 0 | CQ17: 0 | CR17: 0 | CS17: 0 | CT17: 0 | CU17: 0 | CV17: 0 | CW17: 0 | CX17: 0 | CY17: 0 | CZ17: 0 | DA17: 0 | DB17: 0 | DC17: 0 | DD17: 111 | DE17: 8374 | DF17: 0 | DG17: 0 | DH17: 0 | DI17: 0 | DJ17: 0 | DK17: 0 | DL17: 0 | DM17: 0 | DN17: 0 | DO17: 0 | DP17: 0 | DQ17: 0 | DR17: 0 | DS17: 0 | DT17: 0 | DU17: 0 | DV17: 0 | DW17: 0 | DX17: 0 | DY17: 0 | DZ17: 0 | EA17: 0 | EB17: 0 | EC17: 0 | ED17: 0 | EE17: 0 | EF17: 0 | EG17: 0 | EH17: 0 | EI17: 0 | EJ17: 0 | EK17: 0 | EL17: 0 | EM17: 0 | EN17: 0 | EO17: 0 | EP17: 0 | EQ17: 0 | ER17: 0 | ES17: 0 | ET17: 0 | EU17: 0 | EV17: 0 | EW17: 0 | EX17: 0 | EY17: 0 | EZ17: 0 | FA17: 0 | FB17: 0 | FC17: 0 | FD17: 0 | FE17: 0 | FF17: 0 | FG17: 0 | FH17: 0 | FI17: 0 | FJ17: 0 | FK17: 0 | FL17: 81726 | FM17: 0 | FN17: 0 | FO17: 0 | FP17: 0 | FQ17: 0 | FR17: 0 | FS17: 0 | FT17: 0 | FU17: 0 | FV17: 0 | FW17: 0 | FX17: 66240 | FY17: 0 | FZ17: 0 | GA17: 0 | GB17: 29 | GC17: 0 | GD17: 0 | GE17: 0 | GF17: 0 | GG17: 20161317 | GH17: 0 | GI17: 0 | GJ17: 0 | GK17: 0 | GL17: 330141 | GM17: 346 | GN17: 0 | GO17: 330487 | GP17: 20491804 | GQ17: 0 | GR17: 0 | GS17: 0 | GT17: 0 | GU17: 0 | GV17: 0 | GW17: 0 | GX17: 0 | GY17: 0 | GZ17: 20491804 | HA17: 20491804
B18: 13 | C18: Tembakau | D18: 0 | E18: 0 | F18: 0 | G18: 0 | H18: 0 | I18: 0 | J18: 0 | K18: 0 | L18: 0 | M18: 0 | N18: 0 | O18: 0 | P18: 477048 | Q18: 0 | R18: 0 | S18: 0 | T18: 0 | U18: 0 | V18: 0 | W18: 0 | X18: 0 | Y18: 0 | Z18: 0 | AA18: 0 | AB18: 0 | AC18: 0 | AD18: 0 | AE18: 0 | AF18: 0 | AG18: 0 | AH18: 0 | AI18: 0 | AJ18: 0 | AK18: 0 | AL18: 0 | AM18: 0 | AN18: 0 | AO18: 0 | AP18: 0 | AQ18: 0 | AR18: 0 | AS18: 0 | AT18: 0 | AU18: 0 | AV18: 0 | AW18: 0 | AX18: 0 | AY18: 0 | AZ18: 0 | BA18: 0 | BB18: 0 | BC18: 0 | BD18: 0 | BE18: 0 | BF18: 0 | BG18: 0 | BH18: 0 | BI18: 0 | BJ18: 0 | BK18: 0 | BL18: 0 | BM18: 0 | BN18: 0 | BO18: 0 | BP18: 0 | BQ18: 0 | BR18: 0 | BS18: 0 | BT18: 0 | BU18: 0 | BV18: 0 | BW18: 0 | BX18: 0 | BY18: 0 | BZ18: 19255761 | CA18: 1767058 | CB18: 0 | CC18: 0 | CD18: 0 | CE18: 0 | CF18: 0 | CG18: 0 | CH18: 0 | CI18: 0 | CJ18: 0 | CK18: 0 | CL18: 0 | CM18: 0 | CN18: 0 | CO18: 0 | CP18: 0 | CQ18: 0 | CR18: 0 | CS18: 0 | CT18: 0 | CU18: 0 | CV18: 0 | CW18: 0 | CX18: 0 | CY18: 0 | CZ18: 0 | DA18: 0 | DB18: 0 | DC18: 0 | DD18: 26 | DE18: 1674 | DF18: 0 | DG18: 0 | DH18: 0 | DI18: 0 | DJ18: 0 | DK18: 0 | DL18: 0 | DM18: 0 | DN18: 0 | DO18: 0 | DP18: 0 | DQ18: 0 | DR18: 0 | DS18: 0 | DT18: 0 | DU18: 0 | DV18: 0 | DW18: 0 | DX18: 0 | DY18: 0 | DZ18: 0 | EA18: 0 | EB18: 0 | EC18: 0 | ED18: 0 | EE18: 0 | EF18: 0 | EG18: 0 | EH18: 0 | EI18: 0 | EJ18: 0 | EK18: 0 | EL18: 0 | EM18: 0 | EN18: 0 | EO18: 0 | EP18: 0 | EQ18: 0 | ER18: 0 | ES18: 0 | ET18: 0 | EU18: 0 | EV18: 0 | EW18: 0 | EX18: 0 | EY18: 0 | EZ18: 0 | FA18: 0 | FB18: 0 | FC18: 0 | FD18: 0 | FE18: 0 | FF18: 0 | FG18: 0 | FH18: 0 | FI18: 0 | FJ18: 0 | FK18: 0 | FL18: 0 | FM18: 0 | FN18: 0 | FO18: 0 | FP18: 0 | FQ18: 0 | FR18: 0 | FS18: 0 | FT18: 0 | FU18: 0 | FV18: 0 | FW18: 0 | FX18: 234 | FY18: 0 | FZ18: 0 | GA18: 0 | GB18: 0 | GC18: 0 | GD18: 0 | GE18: 0 | GF18: 0 | GG18: 21501801 | GH18: 0 | GI18: 0 | GJ18: 0 | GK18: 0 | GL18: -156071 | GM18: 983105 | GN18: 0 | GO18: 827034 | GP18: 22328835 | GQ18: 0 | GR18: 0 | GS18: 0 | GT18: 0 | GU18: 0 | GV18: 0 | GW18: 0 | GX18: 0 | GY18: 0 | GZ18: 22328835 | HA18: 22328835
... B190: 185 | C190: Jasa Lainnya | D190: 82596 | E190: 48984 | F190: 34 | G190: 32870 | H190: 1927 | I190: 20521 | J190: 1483 | K190: 7082 | L190: 9 | M190: 90399 | N190: 1559 | O190: 0 | P190: 15282 | Q190: 0 | R190: 2484 | S190: 157466 | T190: 0 | U190: 1408 | V190: 392 | W190: 9195 | X190: 29 | Y190: 467 | Z190: 618 | AA190: 1538 | AB190: 1761 | AC190: 0 | AD190: 0 | AE190: 0 | AF190: 0 | AG190: 2715 | AH190: 147366 | AI190: 14028 | AJ190: 0 | AK190: 0 | AL190: 0 | AM190: 0 | AN190: 149940 | AO190: 13360 | AP190: 8627 | AQ190: 76 | AR190: 647 | AS190: 5025 | AT190: 24730 | AU190: 13815 | AV190: 106 | AW190: 139019 | AX190: 77 | AY190: 0 | AZ190: 34 | BA190: 16600 | BB190: 586 | BC190: 530 | BD190: 1170 | BE190: 86 | BF190: 8685 | BG190: 29781 | BH190: 2246 | BI190: 10430 | BJ190: 1652 | BK190: 19098 | BL190: 1597 | BM190: 668 | BN190: 0 | BO190: 0 | BP190: 250 | BQ190: 0 | BR190: 0 | BS190: 0 | BT190: 0 | BU190: 17782 | BV190: 7883 | BW190: 0 | BX190: 808 | BY190: 42395 | BZ190: 92511 | CA190: 7359 | CB190: 347758 | CC190: 210018 | CD190: 25051 | CE190: 22104 | CF190: 31393 | CG190: 233435 | CH190: 23497 | CI190: 32013 | CJ190: 119542 | CK190: 4437 | CL190: 0 | CM190: 0 | CN190: 1960 | CO190: 0 | CP190: 402 | CQ190: 1322 | CR190: 0 | CS190: 25167 | CT190: 91528 | CU190: 62561 | CV190: 19963 | CW190: 37784 | CX190: 4064 | CY190: 9799 | CZ190: 667 | DA190: 11715 | DB190: 15089 | DC190: 55571 | DD190: 555946 | DE190: 8109 | DF190: 63084 | DG190: 76574 | DH190: 8667 | DI190: 210729 | DJ190: 39607 | DK190: 13057 | DL190: 40572 | DM190: 28656 | DN190: 10480 | DO190: 1285 | DP190: 17352 | DQ190: 0 | DR190: 11828 | DS190: 22990 | DT190: 612 | DU190: 0 | DV190: 0 | DW190: 0 | DX190: 0 | DY190: 124 | DZ190: 0 | EA190: 0 | EB190: 0 | EC190: 0 | ED190: 0 | EE190: 0 | EF190: 0 | EG190: 0 | EH190: 20447 | EI190: 16082 | EJ190: 2625 | EK190: 0 | EL190: 17 | EM190: 342 | EN190: 218 | EO190: 247 | EP190: 365 | EQ190: 7825 | ER190: 7254 | ES190: 639067 | ET190: 114386 | EU190: 11265 | EV190: 13307393 | EW190: 38630 | EX190: 31992 | EY190: 185464 | EZ190: 1375311 | FA190: 329617 | FB190: 249884 | FC190: 1983227 | FD190: 2868 | FE190: 3793707 | FF190: 488877 | FG190: 280368 | FH190: 865291 | FI190: 1863852 | FJ190: 299830 | FK190: 6142 | FL190: 35591 | FM190: 126758 | FN190: 781096 | FO190: 2693870 | FP190: 1437394 | FQ190: 61785 | FR190: 356839 | FS190: 53 | FT190: 1895 | FU190: 118708 | FV190: 538884 | FW190: 307702 | FX190: 1356512 | FY190: 163979 | FZ190: 1027464 | GA190: 45253 | GB190: 1614852 | GC190: 588744 | GD190: 223760 | GE190: 34503 | GF190: 4544577 | GG190: 45739110 | GH190: 127026716 | GI190: 158040002 | GJ190: 0 | GK190: 0 | GL190: 0 | GM190: 0 | GN190: 1120547 | GO190: 286187265 | GP190: 331926375 | GQ190: 0 | GR190: 0 | GS190: 0 | GT190: 0 | GU190: 0 | GV190: 0 | GW190: 0 | GX190: 0 | GY190: 0 | GZ190: 331926375 | HA190: 331926375
B191: i.f. | C191: adjustment i.f. | D191: 0 | E191: 0 | F191: 0 | G191: 0 | H191: 0 | I191: 0 | J191: 0 | K191: 0 | L191: 0 | M191: 0 | N191: 0 | O191: 0 | P191: 0 | Q191: 0 | R191: 0 | S191: 0 | T191: 0 | U191: 0 | V191: 0 | W191: 0 | X191: 0 | Y191: 0 | Z191: 0 | AA191: 0 | AB191: 0 | AC191: 0 | AD191: 0 | AE191: 0 | AF191: 0 | AG191: 0 | AH191: 0 | AI191: 0 | AJ191: 0 | AK191: 0 | AL191: 0 | AM191: 0 | AN191: 0 | AO191: 0 | AP191: 0 | AQ191: 0 | AR191: 0 | AS191: 0 | AT191: 0 | AU191: 0 | AV191: 0 | AW191: 0 | AX191: 0 | AY191: 0 | AZ191: 0 | BA191: 0 | BB191: 0 | BC191: 0 | BD191: 0 | BE191: 0 | BF191: 0 | BG191: 0 | BH191: 0 | BI191: 0 | BJ191: 0 | BK191: 0 | BL191: 0 | BM191: 0 | BN191: 0 | BO191: 0 | BP191: 0 | BQ191: 0 | BR191: 0 | BS191: 0 | BT191: 0 | BU191: 0 | BV191: 0 | BW191: 0 | BX191: 0 | BY191: 0 | BZ191: 0 | CA191: 0 | CB191: 0 | CC191: 0 | CD191: 0 | CE191: 0 | CF191: 0 | CG191: 0 | CH191: 0 | CI191: 0 | CJ191: 0 | CK191: 0 | CL191: 0 | CM191: 0 | CN191: 0 | CO191: 0 | CP191: 0 | CQ191: 0 | CR191: 0 | CS191: 0 | CT191: 0 | CU191: 0 | CV191: 0 | CW191: 0 | CX191: 0 | CY191: 0 | CZ191: 0 | DA191: 0 | DB191: 0 | DC191: 0 | DD191: 0 | DE191: 0 | DF191: 0 | DG191: 0 | DH191: 0 | DI191: 0 | DJ191: 0 | DK191: 0 | DL191: 0 | DM191: 0 | DN191: 0 | DO191: 0 | DP191: 0 | DQ191: 0 | DR191: 0 | DS191: 0 | DT191: 0 | DU191: 0 | DV191: 0 | DW191: 0 | DX191: 0 | DY191: 0 | DZ191: 0 | EA191: 0 | EB191: 0 | EC191: 0 | ED191: 0 | EE191: 0 | EF191: 0 | EG191: 0 | EH191: 0 | EI191: 0 | EJ191: 0 | EK191: 0 | EL191: 0 | EM191: 0 | EN191: 0 | EO191: 0 | EP191: 0 | EQ191: 0 | ER191: 0 | ES191: 0 | ET191: 0 | EU191: 0 | EV191: 0 | EW191: 0 | EX191: 0 | EY191: 0 | EZ191: 0 | FA191: 0 | FB191: 0 | FC191: 0 | FD191: 0 | FE191: 0 | FF191: 0 | FG191: 0 | FH191: 0 | FI191: 0 | FJ191: 0 | FK191: 0 | FL191: 0 | FM191: 0 | FN191: 0 | FO191: 0 | FP191: 0 | FQ191: 0 | FR191: 0 | FS191: 0 | FT191: 0 | FU191: 0 | FV191: 0 | FW191: 0 | FX191: 0 | FY191: 0 | FZ191: 0 | GA191: 0 | GB191: 0 | GC191: 0 | GD191: 0 | GE191: 0 | GF191: 0 | GG191: 0 | GH191: 0 | GI191: 0 | GJ191: 0 | GK191: 0 | GL191: 0 | GM191: 0 | GN191: 0 | GO191: 0 | GP191: 0 | GQ191: 0 | GR191: 0 | GS191: 0 | GT191: 0 | GU191: 0 | GV191: 0 | GW191: 0 | GX191: 0 | GY191: 0 | GZ191: 0 | HA191: 0
B192: 1900 | C192: Total Input Antara | D192: 51944458 | E192: 11564392 | F192: 960268 | G192: 7730879 | H192: 371171 | I192: 1055277 | J192: 658100 | K192: 1707859 | L192: 35042 | M192: 32027821 | N192: 1361094 | O192: 5098632 | P192: 5839315 | Q192: 71553 | R192: 6839229 | S192: 34193092 | T192: 1038753 | U192: 14296580 | V192: 5984373 | W192: 89923294 | X192: 7457266 | Y192: 1406094 | Z192: 7591564 | AA192: 4892399 | AB192: 414377 | AC192: 27926966 | AD192: 5415496 | AE192: 70690058 | AF192: 7422429 | AG192: 7752723 | AH192: 14305438 | AI192: 7192315 | AJ192: 44417113 | AK192: 9631981 | AL192: 1980442 | AM192: 7271466 | AN192: 161118549 | AO192: 48693258 | AP192: 93205463 | AQ192: 1069830 | AR192: 4577974 | AS192: 2529448 | AT192: 12469466 | AU192: 2298770 | AV192: 1862586 | AW192: 23654750 | AX192: 512777 | AY192: 96795737 | AZ192: 7944939 | BA192: 745250 | BB192: 10415156 | BC192: 13699903 | BD192: 162542501 | BE192: 39915781 | BF192: 30810744 | BG192: 59627485 | BH192: 15457127 | BI192: 417566030 | BJ192: 14752541 | BK192: 63728577 | BL192: 24003111 | BM192: 1322919 | BN192: 257612227 | BO192: 35664789 | BP192: 37106183 | BQ192: 19265822 | BR192: 29628282 | BS192: 32561595 | BT192: 17882730 | BU192: 38553685 | BV192: 139093576 | BW192: 55894360 | BX192: 1424898 | BY192: 46869455 | BZ192: 82168740 | CA192: 5435364 | CB192: 42868760 | CC192: 75279324 | CD192: 12564693 | CE192: 16057371 | CF192: 20133088 | CG192: 132322485 | CH192: 9936099 | CI192: 6789491 | CJ192: 39117162 | CK192: 22942619 | CL192: 41908368 | CM192: 25628761 | CN192: 10523091 | CO192: 34289512 | CP192: 38365946 | CQ192: 54192135 | CR192: 28206034 | CS192: 41345813 | CT192: 246199282 | CU192: 135741822 | CV192: 36910080 | CW192: 45657760 | CX192: 6272559 | CY192: 18580621 | CZ192: 1165628 | DA192: 35001235 | DB192: 32687409 | DC192: 22921941 | DD192: 42162543 | DE192: 10021729 | DF192: 30161629 | DG192: 54545626 | DH192: 9923676 | DI192: 72055927 | DJ192: 23545095 | DK192: 24367710 | DL192: 33810902 | DM192: 81492439 | DN192: 113202929 | DO192: 5881489 | DP192: 28356124 | DQ192: 2724012 | DR192: 13785516 | DS192: 29648222 | DT192: 49949665 | DU192: 9926570 | DV192: 9454724 | DW192: 26713998 | DX192: 20239351 | DY192: 12484480 | DZ192: 31587935 | EA192: 43613206 | EB192: 5346983 | EC192: 43880708 | ED192: 184470080 | EE192: 15412508 | EF192: 1590936 | EG192: 2277253 | EH192: 9389195 | EI192: 54911028 | EJ192: 43855084 | EK192: 19364045 | EL192: 6199261 | EM192: 7258344 | EN192: 6910501 | EO192: 12215984 | EP192: 15214029 | EQ192: 13595716 | ER192: 560868310 | ES192: 16009377 | ET192: 11270624 | EU192: 10223529 | EV192: 1067551456 | EW192: 85304773 | EX192: 21232330 | EY192: 84778804 | EZ192: 460489905 | FA192: 70715423 | FB192: 56300177 | FC192: 657027492 | FD192: 5895093 | FE192: 351506137 | FF192: 78162645 | FG192: 19125293 | FH192: 149945857 | FI192: 75609937 | FJ192: 28949647 | FK192: 46225537 | FL192: 568839370 | FM192: 65452250 | FN192: 53461903 | FO192: 183113875 | FP192: 81409793 | FQ192: 145402193 | FR192: 30602707 | FS192: 480648 | FT192: 20426780 | FU192: 213570838 | FV192: 199684938 | FW192: 132556380 | FX192: 334978297 | FY192: 74989735 | FZ192: 237829382 | GA192: 4125779 | GB192: 126073397 | GC192: 136074231 | GD192: 40491504 | GE192: 15514544 | GF192: 133585872 | GG192: 11719964690 | GH192: 8290490427 | GI192: 201653378 | GJ192: 1393983295 | GK192: 4429356684 | GL192: -19855373 | GM192: 2466592187 | GN192: 218065238 | GO192: 16980285836 | GP192: 28700250526 | GQ192: 0 | GR192: 0 | GS192: 0 | GT192: 0 | GU192: 0 | GV192: 0 | GW192: 0 | GX192: 0 | GY192: 0 | GZ192: 28700250526 | HA192: 28700250526
B193: 1950 | C193: Pajak Dikurang Subsidi Atas Produk | D193: -9222839 | E193: -2128923 | F193: -65167 | G193: -516214 | H193: -31775 | I193: -65306 | J193: -54938 | K193: -102301 | L193: 760 | M193: -4134188 | N193: -131378 | O193: -480277 | P193: -541191 | Q193: -9382 | R193: -245335 | S193: -3438145 | T193: -103590 | U193: -639596 | V193: -611549 | W193: -2505792 | X193: -290584 | Y193: -219930 | Z193: -892348 | AA193: -460645 | AB193: -44142 | AC193: 129169 | AD193: 25859 | AE193: 322641 | AF193: 47870 | AG193: -442698 | AH193: 128779 | AI193: 52387 | AJ193: 113474 | AK193: -124675 | AL193: -80953 | AM193: -32657 | AN193: 502375 | AO193: 205429 | AP193: 352201 | AQ193: 5467 | AR193: 60524 | AS193: 14664 | AT193: 231455 | AU193: 33559 | AV193: 19873 | AW193: 396195 | AX193: 10771 | AY193: 2362156 | AZ193: 122549 | BA193: 9827 | BB193: 180974 | BC193: 259406 | BD193: 279085 | BE193: 73772 | BF193: 58367 | BG193: 37390 | BH193: 165128 | BI193: 1107168 | BJ193: 28467 | BK193: 492184 | BL193: 303297 | BM193: 2119691 | BN193: 8517 | BO193: 658185 | BP193: 165168 | BQ193: 344454 | BR193: 369244 | BS193: 109906 | BT193: 99317 | BU193: 785182 | BV193: 636263 | BW193: 192074 | BX193: 233504 | BY193: 758304 | BZ193: 6277427 | CA193: 292582 | CB193: 888180 | CC193: 393582 | CD193: 107863 | CE193: 94594 | CF193: 109190 | CG193: 672385 | CH193: 67331 | CI193: 76672 | CJ193: 381780 | CK193: 155959 | CL193: 316416 | CM193: 191103 | CN193: 65720 | CO193: 358119 | CP193: 701156 | CQ193: 1013137 | CR193: 477401 | CS193: 302350 | CT193: 1099703 | CU193: 451599 | CV193: 391940 | CW193: 449132 | CX193: 88322 | CY193: 387157 | CZ193: 20163 | DA193: 669802 | DB193: 367789 | DC193: 245287 | DD193: 467802 | DE193: 81727 | DF193: 119443 | DG193: 92651 | DH193: 42215 | DI193: 1655501 | DJ193: 15866 | DK193: 63502 | DL193: 110083 | DM193: 1420872 | DN193: 91909 | DO193: 125857 | DP193: 1225117 | DQ193: 98088 | DR193: 557697 | DS193: 1639393 | DT193: 3715194 | DU193: 479079 | DV193: 378166 | DW193: 1206281 | DX193: 605302 | DY193: 498616 | DZ193: 1251618 | EA193: 1742070 | EB193: 229030 | EC193: 2230717 | ED193: 3968530 | EE193: 441603 | EF193: 64211 | EG193: 133983 | EH193: 423680 | EI193: 1529859 | EJ193: 642083 | EK193: 846009 | EL193: 101716 | EM193: 119661 | EN193: 97519 | EO193: 773446 | EP193: 356077 | EQ193: 416030 | ER193: 1125255 | ES193: 10866 | ET193: 174062 | EU193: 61725 | EV193: 16771654 | EW193: 3211219 | EX193: 239355 | EY193: 913386 | EZ193: 8834120 | FA193: 439124 | FB193: 380077 | FC193: 5884426 | FD193: 109046 | FE193: 5652560 | FF193: 1228948 | FG193: 289950 | FH193: 3170560 | FI193: 357106 | FJ193: 107571 | FK193: 461150 | FL193: 5372410 | FM193: 441310 | FN193: 166582 | FO193: 699357 | FP193: 397757 | FQ193: 575888 | FR193: 64283 | FS193: 147 | FT193: 67152 | FU193: 865534 | FV193: 1682556 | FW193: 93998 | FX193: 2250985 | FY193: 567934 | FZ193: 2121410 | GA193: 20379 | GB193: 600971 | GC193: 554847 | GD193: 587231 | GE193: 274392 | GF193: 1087295 | GG193: 102083135 | GH193: 317751872 | GI193: 0 | GJ193: 0 | GK193: 147744584 | GL193: -549136 | GM193: 4264318 | GN193: 0 | GO193: 469211638 | GP193: 571294773 | GQ193: 0 | GR193: 0 | GS193: 0 | GT193: 0 | GU193: 0 | GV193: 0 | GW193: 0 | GX193: 0 | GY193: 571294773 | GZ193: 0 | HA193: 571294773
B194: 2000 | C194: Total Konsumsi Antara Impor | D194: 9331300 | E194: 2447735 | F194: 121582 | G194: 871428 | H194: 52490 | I194: 203448 | J194: 282655 | K194: 418573 | L194: 8855 | M194: 8596275 | N194: 262157 | O194: 884574 | P194: 1090265 | Q194: 29532 | R194: 1043847 | S194: 8824151 | T194: 239596 | U194: 1801698 | V194: 1071327 | W194: 6808731 | X194: 456698 | Y194: 345270 | Z194: 1979871 | AA194: 1064908 | AB194: 76488 | AC194: 1097466 | AD194: 212371 | AE194: 2999788 | AF194: 466676 | AG194: 1336398 | AH194: 1258019 | AI194: 542022 | AJ194: 4197131 | AK194: 557879 | AL194: 164912 | AM194: 87380 | AN194: 20014811 | AO194: 4581476 | AP194: 7048477 | AQ194: 72986 | AR194: 828979 | AS194: 165148 | AT194: 2602845 | AU194: 252733 | AV194: 252621 | AW194: 5062981 | AX194: 122737 | AY194: 26462269 | AZ194: 1135942 | BA194: 100959 | BB194: 2061410 | BC194: 3265506 | BD194: 7706616 | BE194: 726793 | BF194: 730849 | BG194: 624000 | BH194: 3820760 | BI194: 10864286 | BJ194: 141819 | BK194: 5628703 | BL194: 3915547 | BM194: 25349770 | BN194: 69349 | BO194: 6107716 | BP194: 6092065 | BQ194: 4360020 | BR194: 4736948 | BS194: 1276237 | BT194: 1336552 | BU194: 19475227 | BV194: 7383417 | BW194: 5260126 | BX194: 2756896 | BY194: 8336886 | BZ194: 13243766 | CA194: 846434 | CB194: 24288585 | CC194: 10846353 | CD194: 2551948 | CE194: 2695894 | CF194: 2946843 | CG194: 37682089 | CH194: 1871643 | CI194: 1683562 | CJ194: 10356748 | CK194: 2121137 | CL194: 5106550 | CM194: 2784390 | CN194: 917319 | CO194: 6774946 | CP194: 12041468 | CQ194: 15692042 | CR194: 6083289 | CS194: 6651617 | CT194: 56862084 | CU194: 21141388 | CV194: 6341487 | CW194: 21789828 | CX194: 3235815 | CY194: 9535385 | CZ194: 830894 | DA194: 14649983 | DB194: 10277171 | DC194: 8619728 | DD194: 12025360 | DE194: 1960419 | DF194: 2261947 | DG194: 2107043 | DH194: 696637 | DI194: 29949600 | DJ194: 3231639 | DK194: 2997681 | DL194: 3070810 | DM194: 25797243 | DN194: 2200647 | DO194: 644439 | DP194: 15250875 | DQ194: 727893 | DR194: 7216959 | DS194: 20349447 | DT194: 49581070 | DU194: 7131197 | DV194: 4429747 | DW194: 14500092 | DX194: 7388842 | DY194: 5894993 | DZ194: 15568933 | EA194: 24178149 | EB194: 2519874 | EC194: 29141647 | ED194: 40275003 | EE194: 5428899 | EF194: 820310 | EG194: 1950783 | EH194: 5140251 | EI194: 19808773 | EJ194: 8948789 | EK194: 11686213 | EL194: 1670125 | EM194: 2120517 | EN194: 2361816 | EO194: 5190247 | EP194: 5683212 | EQ194: 4294579 | ER194: 19487928 | ES194: 496528 | ET194: 3047366 | EU194: 1614980 | EV194: 202244551 | EW194: 38673675 | EX194: 2643253 | EY194: 10209099 | EZ194: 100921064 | FA194: 6877665 | FB194: 8383176 | FC194: 69110502 | FD194: 647298 | FE194: 47074349 | FF194: 11245539 | FG194: 2804208 | FH194: 23077628 | FI194: 7711967 | FJ194: 2090347 | FK194: 4038695 | FL194: 41370569 | FM194: 7501170 | FN194: 4141259 | FO194: 19458838 | FP194: 10500610 | FQ194: 15824225 | FR194: 2035886 | FS194: 20084 | FT194: 1269506 | FU194: 16691787 | FV194: 26810944 | FW194: 13745266 | FX194: 27919990 | FY194: 7219680 | FZ194: 30405470 | GA194: 431236 | GB194: 18155644 | GC194: 16568429 | GD194: 3627047 | GE194: 3582576 | GF194: 10661667 | GG194: 1828980745 | GH194: 304296843 | GI194: 0 | GJ194: 892242 | GK194: 319949207 | GL194: -31974741 | GM194: 0 | GN194: 0 | GO194: 593163551 | GP194: 2422144296 | GQ194: 2060113093 | GR194: 362031203 | GS194: 0 | GT194: 2422144296 | GU194: 0 | GV194: 0 | GW194: 0 | GX194: 0 | GY194: 0 | GZ194: 0 | HA194: 2422144296
B195: 2010 | C195: Kompensasi Tenaga Kerja | D195: 97638664 | E195: 22528109 | F195: 2028894 | G195: 21507545 | H195: 627723 | I195: 1704462 | J195: 1182994 | K195: 2553317 | L195: 83996 | M195: 52568032 | N195: 1825419 | O195: 4378250 | P195: 5658858 | Q195: 130274 | R195: 16343978 | S195: 42926520 | T195: 2706879 | U195: 28696920 | V195: 11517615 | W195: 89753183 | X195: 15931151 | Y195: 2539787 | Z195: 20588436 | AA195: 9985531 | AB195: 931185 | AC195: 32740142 | AD195: 5506064 | AE195: 60752161 | AF195: 4445618 | AG195: 9502497 | AH195: 36782000 | AI195: 17759907 | AJ195: 85616411 | AK195: 18606176 | AL195: 2568396 | AM195: 28237943 | AN195: 46899455 | AO195: 31272162 | AP195: 24915689 | AQ195: 603392 | AR195: 1940651 | AS195: 1151942 | AT195: 5607999 | AU195: 606633 | AV195: 787394 | AW195: 16339433 | AX195: 331546 | AY195: 67626338 | AZ195: 8027677 | BA195: 697446 | BB195: 9697926 | BC195: 8094910 | BD195: 25811848 | BE195: 6647761 | BF195: 3906450 | BG195: 7070402 | BH195: 2536297 | BI195: 36362969 | BJ195: 1688220 | BK195: 16106872 | BL195: 3650684 | BM195: 3459371 | BN195: 19529911 | BO195: 6679875 | BP195: 7354505 | BQ195: 3029388 | BR195: 4076041 | BS195: 3804857 | BT195: 5717488 | BU195: 8574212 | BV195: 19571505 | BW195: 4230731 | BX195: 1141998 | BY195: 9349932 | BZ195: 35482301 | CA195: 1229853 | CB195: 14531869 | CC195: 15662924 | CD195: 2933864 | CE195: 3429676 | CF195: 3800260 | CG195: 30281807 | CH195: 4639352 | CI195: 4728868 | CJ195: 27223776 | CK195: 6068713 | CL195: 13196418 | CM195: 6916358 | CN195: 2868176 | CO195: 7917060 | CP195: 12331380 | CQ195: 13640066 | CR195: 6248374 | CS195: 17663077 | CT195: 34136492 | CU195: 25982587 | CV195: 6549569 | CW195: 8375705 | CX195: 1394547 | CY195: 6069064 | CZ195: 402524 | DA195: 6585318 | DB195: 6778651 | DC195: 5640938 | DD195: 14790535 | DE195: 2366700 | DF195: 4716449 | DG195: 6817854 | DH195: 1700558 | DI195: 18248684 | DJ195: 8750265 | DK195: 9848724 | DL195: 14815735 | DM195: 19476676 | DN195: 11381200 | DO195: 1243051 | DP195: 12275152 | DQ195: 1071296 | DR195: 6461925 | DS195: 15351641 | DT195: 30931562 | DU195: 4283361 | DV195: 3614215 | DW195: 13679656 | DX195: 9939089 | DY195: 4760032 | DZ195: 11222594 | EA195: 15652062 | EB195: 1093549 | EC195: 13590066 | ED195: 87240369 | EE195: 9532233 | EF195: 772728 | EG195: 1761170 | EH195: 6952285 | EI195: 33961576 | EJ195: 19018341 | EK195: 6140408 | EL195: 1895496 | EM195: 2697564 | EN195: 2251478 | EO195: 4055560 | EP195: 4038130 | EQ195: 3715944 | ER195: 30058878 | ES195: 3516985 | ET195: 7236460 | EU195: 2736857 | EV195: 427367547 | EW195: 13701045 | EX195: 6560731 | EY195: 31169928 | EZ195: 157275705 | FA195: 86534514 | FB195: 78857009 | FC195: 727346858 | FD195: 5350854 | FE195: 131007599 | FF195: 15042379 | FG195: 7013244 | FH195: 41691538 | FI195: 42303854 | FJ195: 12052781 | FK195: 33221549 | FL195: 224402080 | FM195: 18680032 | FN195: 42007602 | FO195: 104298275 | FP195: 33688930 | FQ195: 195528197 | FR195: 36631253 | FS195: 923306 | FT195: 23911792 | FU195: 67220608 | FV195: 68982097 | FW195: 116722507 | FX195: 334181165 | FY195: 262518545 | FZ195: 80894553 | GA195: 1357430 | GB195: 162999870 | GC195: 72408919 | GD195: 14831757 | GE195: 9252893 | GF195: 120731971 | GG195: 5810802524
